Workbook

Sheet Stages
A1: TICVAI - AWS cloud specs and cost, staged (Stage 1 launch; Stage 2 = the full cell sheets)
B3: AED per USD | C3: 3.6725 | D3: Edit the rate, the margin and any unit price; every total is a formula.
B4: Margin | C4: 0.2 | D4: Prices: per line, from the AWS Price List API (me-central-1) pulled 4 October 2026; the AWS rates sheet has each rate and its file.
A6: Environment | B6: Group | C6: AWS service type | D6: Service description | E6: Region | F6: Specs description | G6: Qty | H6: Unit price (USD / month) | I6: Estimated monthly cost (USD)
A7: Stage 1 production (launch) | B7: Compute (EKS) | C7: Amazon EKS | D7: Control plane | E7: me-central-1 (UAE) | F7: $0.10/h. EKS has no free tier (AKS Free at Stage 1 on Azure) | G7: 1 | H7: 73 | I7: =G7*H7
B8: Compute (EKS) | C8: EC2 (EKS managed node group) | D8: Two nodes running every deployable, Redis, Qdrant and the broker in-cluster | E8: me-central-1 (UAE) | F8: m6i.2xlarge (8 vCPU, 32 GiB), Linux, $0.4708/h, one per AZ. The same images and Helm chart as the cell; one replica per deployable across the two nodes (ADR-0061 as amended 4 October: the floors apply from Stage 2) | G8: 2 | H8: 343.68 | I8: =G8*H8
B9: Compute (EKS) | C9: EBS (gp3) | D9: Node root volumes | E9: me-central-1 (UAE) | F9: gp3 80 GB per node at $0.0968 per GB-month ($7.74 a node), 3 nodes. The Azure sheets carry no OS-disk line (the two nodes and the GPU node) | G9: 3 | H9: 7.74 | I9: =G9*H9
B10: Vector store | C10: EBS (gp3) | D10: Qdrant storage (single in-cluster node) | E10: me-central-1 (UAE) | F10: gp3 256 GB | G10: 1 | H10: 24.78 | I10: =G10*H10
B11: Event broker | C11: EBS (gp3) | D11: Broker storage (RabbitMQ single in-cluster node) | E11: me-central-1 (UAE) | F11: gp3 128 GB | G11: 1 | H11: 12.39 | I11: =G11*H11
B12: Cache | C12: EBS (gp3) | D12: Redis persistence (single in-cluster node, append-only file) | E12: me-central-1 (UAE) | F12: gp3 128 GB | G12: 1 | H12: 12.39 | I12: =G12*H12
B13: Network | C13: Elastic Load Balancing (ALB) | D13: Ingress: an internal ALB, CloudFront's VPC origin | E13: me-central-1 (UAE) | F13: $0.028224/h ($20.60) + about 1 LCU on average at $0.00896 per LCU-hour ($6.54, an assumption). AWS Load Balancer Controller on the system node group | G13: 1 | H13: 27.14 | I13: =G13*H13
B14: Network | C14: NAT Gateway | D14: One static egress IP for the payment, e-invoicing and messaging allow-lists | E14: me-central-1 (UAE) | F14: 1 zonal NAT Gateway at $0.0528/h ($38.54) + 1 TB processed at $0.0528/GB ($54.07) + 1 Elastic IP at $0.005/h ($3.65). The nodes stay in private subnets (on Azure the load balancer's outbound rule carries the IP) | G14: 1 | H14: 96.26 | I14: =G14*H14
B15: Database | C15: Amazon RDS for PostgreSQL | D15: Primary with a Multi-AZ standby: control DB + DB per tenant | E15: me-central-1 (UAE) | F15: PostgreSQL 16, db.m6g.xlarge Multi-AZ, $0.772/h: ADR-0060 holds at every stage. No read or reporting replica at launch | G15: 1 | H15: 563.56 | I15: =G15*H15
B16: Database | C16: Amazon RDS for PostgreSQL | D16: Storage, primary and standby | E16: me-central-1 (UAE) | F16: gp3 256 GB Multi-AZ at $0.279; PITR 35 days | G16: 1 | H16: 71.42 | I16: =G16*H16
B17: AI | C17: EC2 (EKS managed node group) | D17: AI GPU node: ticvai-ai, Presidio, the Arabic NER, BGE-M3 and its reranker (CHG-R11-001) | E17: me-central-1 (UAE) | F17: g6.2xlarge (8 vCPU, 32 GiB, 1 x NVIDIA L4 24 GB), $1.20043/h, tainted. Offered in me-central-1 (EC2 price list of 25 September); g6 capacity in each AZ to confirm. Carries the floors (real-time 2, interactive 1, batch 0, about 1 vCPU a pod), Presidio on the CPU, and on the GPU BGE-M3, its reranker and the Arabic NER; never an LLM. g6.xlarge ($721.42) has 4 vCPU, too few for the AI pods beside Presidio; g5.xlarge ($900.82) costs more with 4 vCPU; g5.2xlarge $1,085.28. One node; the AI log tables live in the main PostgreSQL at launch | G17: 1 | H17: 876.31 | I17: =G17*H17
B18: Storage | C18: Amazon S3 | D18: Media (including venue 3D models), exports, snapshots, dumps | E18: me-central-1 (UAE) | F18: S3 Standard, 2,048 GB, me-central-1 only | G18: 1 | H18: 51.2 | I18: =G18*H18
B19: Storage | C19: Amazon ECR | D19: Images for the five deployables | E19: me-central-1 (UAE) | F19: About 100 GB | G19: 1 | H19: 10 | I19: =G19*H19
... B26: AI (usage) | C26: LLM providers | D26: Language model calls (re-billed per token, AI-D02) | E26: me-central-1 (UAE) | F26: Usage-based | G26: 1 | H26: 0 | I26: =G26*H26
F27: USD - Total cost per month | I27: =SUM(I7:I26)
F28: AED - Total cost per month | I28: =I27*$C$3
F29: AED - Total cost per year | I29: =I28*12
F30: AED - Total price per year with margin | I30: =I29*(1+$C$4)
B32: Notes - Stage 1 production (launch)
B33: Staged as on Azure (Chinmay, 4 October 2026, CHG-R11-003): launch on Stage 1, move to Stage 2 (the full cell on the other two sheets) on the same triggers as the Azure Stages sheet: a paying venue needing ADR-0060's targets, traffic beyond Stage 1 sustained, a large on-sale booked, or a client needing Bot Control or a private origin.
B34: Stage 1 on AWS differs from Azure's in three lines: the EKS control plane ($73; AKS Free on Azure), a NAT Gateway for the static egress IP (on Azure the load balancer's outbound rule carries it), and the GPU node (g6.2xlarge, a whole L4). WAF on CloudFront carries AWS's managed core rule set even at launch; Bot Control waits for Stage 2.
B35: Not included at Stage 1: GuardDuty, Inspector, Security Hub, VPC interface endpoints, ElastiCache, the AI log instance, read and reporting replicas: each comes with Stage 2. Session Manager has no charge line.
B36: Stage 0 is a reference line only (one m6i.4xlarge and the GPU node): it is not the plan. The 25 September AWS board's $716 for it included more than the instance.
A39: Environment | B39: Group | C39: AWS service type | D39: Service description | E39: Region | F39: Specs description | G39: Qty | H39: Unit price (USD / month) | I39: Estimated monthly cost (USD)
A40: Stage 1 pre-production | B40: Compute (EKS) | C40: Amazon EKS | D40: Control plane | E40: me-central-1 (UAE) | F40: $0.10/h, a cluster of its own (a namespace on the Stage 1 cluster would save it) | G40: 1 | H40: 73 | I40: =G40*H40
B41: Compute (EKS) | C41: EC2 (EKS managed node group) | D41: One node: every deployable, Redis, Qdrant and the broker | E41: me-central-1 (UAE) | F41: m6i.2xlarge (8 vCPU, 32 GiB), one replica each. No GPU node: the models run on its CPU at test volume (an assumption to confirm in Sprint 2) | G41: 1 | H41: 343.68 | I41: =G41*H41
B42: Compute (EKS) | C42: EBS (gp3) | D42: Node root volume | E42: me-central-1 (UAE) | F42: gp3 80 GB per node at $0.0968 per GB-month ($7.74 a node), 1 nodes. The Azure sheets carry no OS-disk line | G42: 1 | H42: 7.74 | I42: =G42*H42
B43: Database | C43: Amazon RDS for PostgreSQL | D43: Control DB + test tenant DBs | E43: me-central-1 (UAE) | F43: db.m6g.large single-AZ + gp3 256 GB, no standby (pre-production only) | G43: 1 | H43: 176.73 | I43: =G43*H43
B44: Storage | C44: Amazon S3 | D44: Test media and snapshots | E44: me-central-1 (UAE) | F44: S3 Standard, 500 GB | G44: 1 | H44: 12.5 | I44: =G44*H44
B45: Security | C45: AWS Secrets Manager | D45: Test secrets | E45: me-central-1 (UAE) | F45: About 5 secrets at $0.40 | G45: 5 | H45: 0.4 | I45: =G45*H45
B46: Network | C46: CloudFront, WAF, ALB, NAT, ECR, CloudWatch | D46: Shared with Stage 1 production | E46: me-central-1 (UAE) | F46: Separate behaviours and web ACL rules | G46: 1 | H46: 0 | I46: =G46*H46
F47: USD - Total cost per month | I47: =SUM(I40:I46)
F48: AED - Total cost per month | I48: =I47*$C$3
F49: AED - Total cost per year | I49: =I48*12
F50: AED - Total price per year with margin | I50: =I49*(1+$C$4)
B52: Notes - Stage 1 pre-production
...

Sheet Infra without HA
A1: TICVAI - AWS cloud specs and cost (infra without ha)
B3: AED per USD | C3: 3.6725 | D3: Edit the rate, the margin and any unit price; every total is a formula.
B4: Margin | C4: 0.2 | D4: Prices: AWS Price List API, public bulk offer files (pricing.us-east-1.amazonaws.com/offers/v1.0/aws/<service>/current/me-central-1/index.json; CloudFront's global file), region me-central-1 (Middle East, UAE), on demand, Linux, 730 hours a month, pulled 4 October 2026 (files published 11 September to 3 October 2026; each rate names its file and date in AWS_RATE).
A6: Environment | B6: Group | C6: AWS service type | D6: Service description | E6: Region | F6: Specs description | G6: Qty | H6: Unit price (USD / month) | I6: Estimated monthly cost (USD) | J6: When solution is scaled up (USD)
A7: Production | B7: Compute (EKS) | C7: Amazon EKS | D7: Control plane, standard support | E7: me-central-1 (UAE) | F7: $0.10/h; uptime SLA included | G7: 1 | H7: 73 | I7: =G7*H7 | J7: =I7
B8: Compute (EKS) | C8: EC2 (EKS managed node group) | D8: System node group (and the ingress controller pods) | E8: me-central-1 (UAE) | F8: m6i.xlarge (4 vCPU, 16 GiB), Linux, one AZ | G8: 2 | H8: 171.84 | I8: =G8*H8 | J8: =I8
B9: Compute (EKS) | C9: EC2 (EKS managed node group) | D9: Workload node group: commerce, access, operations, workers | E9: me-central-1 (UAE) | F9: m6i.2xlarge (8 vCPU, 32 GiB), autoscale 2-10. Carries the floors (ADR-0061): 9 replicas on 2 nodes; in one AZ commerce's three replicas cannot be one per AZ | G9: 2 | H9: 343.68 | I9: =G9*H9 | J9: =4*H9
B10: Compute (EKS) | C10: EC2 (EKS managed node group) | D10: AI GPU node group: ticvai-ai, BGE-M3 and its reranker, Presidio and the Arabic NER (CHG-R11-001) | E10: me-central-1 (UAE) | F10: g6.2xlarge (8 vCPU, 32 GiB, 1 x NVIDIA L4 24 GB), $1.20043/h, tainted. Offered in me-central-1 (EC2 price list of 25 September); g6 capacity in each AZ to confirm. Carries the floors (real-time 2, interactive 1, batch 0, about 1 vCPU a pod), Presidio on the CPU, and on the GPU BGE-M3, its reranker and the Arabic NER; never an LLM. g6.xlarge ($721.42) has 4 vCPU, too few for the AI pods beside Presidio; g5.xlarge ($900.82) costs more with 4 vCPU; g5.2xlarge $1,085.28. One node. With it down the scrubber is down and LLM calls are refused (503 scrubber-unavailable), never sent raw | G10: 1 | H10: 876.31 | I10: =G10*H10 | J10: =2*H10
B11: Compute (EKS) | C11: EBS (gp3) | D11: Node root volumes | E11: me-central-1 (UAE) | F11: gp3 80 GB per node at $0.0968 per GB-month ($7.74 a node), 7 nodes. The Azure sheets carry no OS-disk line (2 system, 2 workload, 1 GPU, 1 qdrant, 1 broker; 10 scaled up) | G11: 7 | H11: 7.74 | I11: =G11*H11 | J11: =10*H11
B12: Vector store | C12: EC2 (EKS managed node group) | D12: Qdrant, one collection per tenant (ADR-0049) | E12: me-central-1 (UAE) | F12: r6i.xlarge (4 vCPU, 32 GiB), single node | G12: 1 | H12: 226.45 | I12: =G12*H12 | J12: =I12
B13: Vector store | C13: EBS (gp3) | D13: Qdrant storage | E13: me-central-1 (UAE) | F13: gp3 256 GB | G13: 1 | H13: 24.78 | I13: =G13*H13 | J13: =I13
B14: Event broker | C14: EC2 (EKS managed node group) | D14: Broker: RabbitMQ recommended, or Kafka (the client's choice; ADR-0057, proposed) | E14: me-central-1 (UAE) | F14: m6i.large (2 vCPU, 8 GiB), single node, self-run | G14: 1 | H14: 85.92 | I14: =G14*H14 | J14: =I14
B15: Event broker | C15: EBS (gp3) | D15: Broker storage | E15: me-central-1 (UAE) | F15: gp3 128 GB | G15: 1 | H15: 12.39 | I15: =G15*H15 | J15: =I15
B16: Database | C16: Amazon RDS for PostgreSQL | D16: Primary with a Multi-AZ standby: control DB + DB per tenant | E16: me-central-1 (UAE) | F16: PostgreSQL 16, db.m6g.xlarge Multi-AZ, $0.772/h. The standby stays on this sheet: production PostgreSQL is zone-redundant on every tier (ADR-0060; Chinmay, 1 October) | G16: 1 | H16: 563.56 | I16: =G16*H16 | J16: =I16
B17: Database | C17: Amazon RDS for PostgreSQL | D17: Storage, primary and standby | E17: me-central-1 (UAE) | F17: gp3 256 GB Multi-AZ at $0.279; PITR 35 days | G17: 1 | H17: 71.42 | I17: =G17*H17 | J17: =I17
B18: Database | C18: Amazon RDS for PostgreSQL | D18: Read replica (operational reads; gate checks never read here) | E18: me-central-1 (UAE) | F18: db.m6g.xlarge single-AZ + gp3 256 GB | G18: 1 | H18: 317.62 | I18: =G18*H18 | J18: =I18
B19: Database | C19: Amazon RDS for PostgreSQL | D19: Reporting replica (lag-tolerant, no writes) | E19: me-central-1 (UAE) | F19: db.m6g.large + gp3 256 GB. Reporting never reads an operational replica (ADR-0016) | G19: 1 | H19: 176.73 | I19: =G19*H19 | J19: =I19
B20: Database | C20: Amazon RDS for PostgreSQL | D20: AI log database | E20: me-central-1 (UAE) | F20: db.m6g.large + gp3 512 GB | G20: 1 | H20: 212.57 | I20: =G20*H20 | J20: =I20
B21: Cache | C21: Amazon ElastiCache (Valkey) | D21: Sessions, idempotency keys, request budgets, waiting-room positions, caches | E21: me-central-1 (UAE) | F21: cache.r7g.large (13.07 GiB), one node, no replica; $0.2142/h. A production cell without the replica is the client's call (ADR-0060) | G21: 1 | H21: 156.37 | I21: =G21*H21 | J21: =I21
B22: Storage | C22: Amazon S3 | D22: Media (including venue 3D models), exports, Qdrant snapshots, database dumps | E22: me-central-1 (UAE) | F22: S3 Standard, 2,048 GB, me-central-1 only (S3 has no single-AZ hot class: One Zone-IA is infrequent access) | G22: 1 | H22: 51.2 | I22: =G22*H22 | J22: =I22
B23: Storage | C23: Amazon ECR | D23: Images for the five deployables | E23: me-central-1 (UAE) | F23: About 100 GB | G23: 1 | H23: 10 | I23: =G23*H23 | J23: =I23
... B25: Security | C25: AWS KMS | D25: Platform and per-tenant keys | E25: me-central-1 (UAE) | F25: 5 customer managed keys at $1 (+$1 a tenant a month) | G25: 5 | H25: 1 | I25: =G25*H25 | J25: =I25
B26: Network | C26: Amazon CloudFront | D26: Single entry for web, apps and APIs; the on-sale waiting-room page | E26: Global (edge) | F26: 2,048 GB to viewers in the Middle East at $0.110/GB ($225.28) + about 50 million HTTPS requests at $0.0120 per 10,000 ($60.00). Origin fetches from the ALB are free; a VPC origin keeps the ALB private (no charge line in the price list, to confirm) | G26: 1 | H26: 285.28 | I26: =G26*H26 | J26: =2*H26
B27: Network | C27: AWS WAF | D27: WAF on CloudFront: OWASP and bot rules, rate rules per client IP | E27: Global (edge) | F27: Web ACL $5 + about 8 rules and managed rule groups (AWS managed core rule set for OWASP, rate-based rules per client IP) at $1 ($8.00) + 50 million requests at $0.60 per million ($30.00) + Bot Control (common) $10 + 40 million requests beyond the first 10 million at $1 per million ($40.00). A CloudFront web ACL is global: the me-central-1 rates, to confirm on the bill | G27: 1 | H27: 93 | I27: =G27*H27 | J27: =2*H27
B28: Network | C28: Elastic Load Balancing (ALB) | D28: Ingress: an internal ALB, CloudFront's VPC origin | E28: me-central-1 (UAE) | F28: $0.028224/h ($20.60) + about 2 LCU on average at $0.00896 per LCU-hour ($13.08, an assumption). AWS Load Balancer Controller on the system node group | G28: 1 | H28: 33.68 | I28: =G28*H28 | J28: =2*H28
B29: Network | C29: NAT Gateway | D29: One static egress IP for the allow-lists | E29: me-central-1 (UAE) | F29: 1 zonal NAT Gateway at $0.0528/h ($38.54) + 1 TB processed at $0.0528/GB ($54.07) + 1 Elastic IP at $0.005/h ($3.65) | G29: 1 | H29: 96.26 | I29: =G29*H29 | J29: =I29
B30: Network | C30: Systems Manager Session Manager | D30: Administrative access only | E30: me-central-1 (UAE) | F30: No charge line in the price list, to confirm | G30: 1 | H30: 0 | I30: =G30*H30 | J30: =I30
B31: Network | C31: AWS PrivateLink (VPC endpoints) | D31: Private endpoints and private DNS. No store has a public endpoint, with or without HA | E31: me-central-1 (UAE) | F31: 6 interface endpoints (ECR api and dkr, Secrets Manager, KMS, STS, CloudWatch Logs) x 1 AZ at $0.0121/h ($53.00) + about 100 GB processed at $0.01/GB ($1.00); S3 through a gateway endpoint (free); Route 53 private hosted zones | G31: 1 | H31: 54 | I31: =G31*H31 | J31: =I31
B32: Network | C32: Data transfer out | D32: Egress through the NAT Gateway to providers | E32: me-central-1 (UAE) | F32: About 200 GB a month: the first 100 GB free, then $0.117/GB ($11.70). The ALB-to-CloudFront traffic is free; the web traffic is in the CloudFront line | G32: 1 | H32: 11.7 | I32: =G32*H32 | J32: =2*H32
B33: Operations | C33: Amazon CloudWatch | D33: Logs, metrics, alerts | E33: me-central-1 (UAE) | F33: About 40 GB of logs ingested at $0.63/GB ($25.20), stored at $0.033 per GB-month ($1.32 in the first month, growing with retention), about 150 custom metrics at $0.30 ($45.00) | G33: 1 | H33: 71.52 | I33: =G33*H33 | J33: =I33
B34: Operations | C34: AWS Backup | D34: Snapshots of the Qdrant and broker volumes | E34: me-central-1 (UAE) | F34: About 200 GB of incremental EBS snapshots at $0.055 per GB-month | G34: 1 | H34: 11 | I34: =G34*H34 | J34: =I34
B35: Operations | C35: GuardDuty, Inspector, Security Hub | D35: Threat detection, scanning, posture | E35: me-central-1 (UAE) | F35: GuardDuty EKS Runtime Monitoring 38 vCPU x $1.58 ($60.04); RDS Protection 12 vCPU x $1.03 ($12.36); VPC flow and DNS logs about 15 GB x $1.25 ($18.75) and about 2 million CloudTrail events ($10.00); Inspector 7 instances x 730 h x $0.0021 ($10.73); Security Hub Essentials 7 instances x 730 h x $0.0056944 ($29.10). Volumes are assumptions | G35: 1 | H35: 140.98 | I35: =G35*H35 | J35: =I35
B36: AI (usage) | C36: LLM providers | D36: Language model calls (re-billed per token, AI-D02) | E36: me-central-1 (UAE) | F36: Usage-based | G36: 1 | H36: 0 | I36: =G36*H36 | J36: =I36
F37: USD - Total cost per month | I37: =SUM(I7:I36) | J37: =SUM(J7:J36)
F38: AED - Total cost per month | I38: =I37*$C$3 | J38: =J37*$C$3
F39: AED - Total cost per year | I39: =I38*12
F40: AED - Total price per year with margin | I40: =I39*(1+$C$4)
B42: Notes - Production
B43: Prices: AWS Price List API, public bulk offer files (pricing.us-east-1.amazonaws.com/offers/v1.0/aws/<service>/current/me-central-1/index.json; CloudFront's global file), region me-central-1 (Middle East, UAE), on demand, Linux, 730 hours a month, pulled 4 October 2026 (files published 11 September to 3 October 2026; each rate names its file and date in AWS_RATE). Savings Plans or reserved instances (1 or 3 years) lower compute by roughly 30-60%; confirm each line in the AWS Pricing Calculator for me-central-1 before quoting.
B44: The same cell as the Azure sheets, service for service (the AWS LLD, TICVAI-LLD-AWS.md, has the mapping): the same five node groups and ADR-0061 floors, the same stores, the same entry. Region me-central-1 (Middle East, UAE), three AZs; every store stays in the UAE.
...

Sheet Infra with High Availability
A1: TICVAI - AWS cloud specs and cost (infra with high availability)
B3: AED per USD | C3: 3.6725 | D3: Edit the rate, the margin and any unit price; every total is a formula.
B4: Margin | C4: 0.2 | D4: Prices: AWS Price List API, public bulk offer files (pricing.us-east-1.amazonaws.com/offers/v1.0/aws/<service>/current/me-central-1/index.json; CloudFront's global file), region me-central-1 (Middle East, UAE), on demand, Linux, 730 hours a month, pulled 4 October 2026 (files published 11 September to 3 October 2026; each rate names its file and date in AWS_RATE).
A6: Environment | B6: Group | C6: AWS service type | D6: Service description | E6: Region | F6: Specs description | G6: Qty | H6: Unit price (USD / month) | I6: Estimated monthly cost (USD) | J6: When solution is scaled up (USD)
A7: Production | B7: Compute (EKS) | C7: Amazon EKS | D7: Control plane, standard support | E7: me-central-1 (UAE) | F7: $0.10/h; the uptime SLA is included (the AKS Standard tier line) | G7: 1 | H7: 73 | I7: =G7*H7 | J7: =I7
B8: Compute (EKS) | C8: EC2 (EKS managed node group) | D8: System node group (and the ingress controller pods) | E8: me-central-1 (UAE) | F8: m6i.xlarge (4 vCPU, 16 GiB; the D4s v5 line), Linux, $0.2354/h, autoscale 2-4 across AZs a-c; budgeted at 3, one per AZ | G8: 3 | H8: 171.84 | I8: =G8*H8 | J8: =I8
B9: Compute (EKS) | C9: EC2 (EKS managed node group) | D9: Workload node group: commerce, access, operations, workers | E9: me-central-1 (UAE) | F9: m6i.2xlarge (8 vCPU, 32 GiB; the D8s v5 line), $0.4708/h, autoscale 3-20 across AZs. Carries ADR-0061's floors as on Azure: 9 replicas, commerce one per AZ. Scaled up, 6 nodes | G9: 3 | H9: 343.68 | I9: =G9*H9 | J9: =6*H9
B10: Compute (EKS) | C10: EC2 (EKS managed node group) | D10: AI GPU node group: ticvai-ai, BGE-M3 and its reranker, Presidio and the Arabic NER (CHG-R11-001) | E10: me-central-1 (UAE) | F10: g6.2xlarge (8 vCPU, 32 GiB, 1 x NVIDIA L4 24 GB), $1.20043/h, tainted. Offered in me-central-1 (EC2 price list of 25 September); g6 capacity in each AZ to confirm. Carries the floors (real-time 2, interactive 1, batch 0, about 1 vCPU a pod), Presidio on the CPU, and on the GPU BGE-M3, its reranker and the Arabic NER; never an LLM. g6.xlarge ($721.42) has 4 vCPU, too few for the AI pods beside Presidio; g5.xlarge ($900.82) costs more with 4 vCPU; g5.2xlarge $1,085.28. One node per AZ | G10: 2 | H10: 876.31 | I10: =G10*H10 | J10: =4*H10
B11: Compute (EKS) | C11: EBS (gp3) | D11: Node root volumes | E11: me-central-1 (UAE) | F11: gp3 80 GB per node at $0.0968 per GB-month ($7.74 a node), 14 nodes. The Azure sheets carry no OS-disk line (3 system, 3 workload, 2 GPU, 3 qdrant, 3 broker; 19 scaled up) | G11: 14 | H11: 7.74 | I11: =G11*H11 | J11: =19*H11
B12: Vector store | C12: EC2 (EKS managed node group) | D12: Qdrant cluster, one collection per tenant (ADR-0049) | E12: me-central-1 (UAE) | F12: qdrant node group: r6i.xlarge (4 vCPU, 32 GiB; the E4s v5 line), $0.3102/h, x3 one per AZ, replication factor 2, TLS, collection-scoped JWT per tenant; tainted ticvai.io/pool=data | G12: 3 | H12: 226.45 | I12: =G12*H12 | J12: =I12
B13: Vector store | C13: EBS (gp3) | D13: Qdrant storage | E13: me-central-1 (UAE) | F13: gp3 256 GB per node at $0.0968 per GB-month. Snapshots per collection go to S3 by a CronJob | G13: 3 | H13: 24.78 | I13: =G13*H13 | J13: =I13
B14: Event broker | C14: EC2 (EKS managed node group) | D14: Broker cluster: RabbitMQ recommended, or Kafka (the client's choice; ADR-0057, proposed) | E14: me-central-1 (UAE) | F14: broker node group: m6i.large (2 vCPU, 8 GiB; the D2s v5 line), $0.1177/h, x3 across AZs, self-run with the RabbitMQ Cluster Operator, as on Azure (broker_self_hosted). Managed alternative: Amazon MQ for RabbitMQ, 3-node mq.m7g.large cluster at $1.005/h ($733.65) plus storage at $0.121 per GB-month; CloudAMQP in me-central-1 to confirm | G14: 3 | H14: 85.92 | I14: =G14*H14 | J14: =I14
B15: Event broker | C15: EBS (gp3) | D15: Broker storage: quorum queues or Kafka logs | E15: me-central-1 (UAE) | F15: gp3 128 GB per node | G15: 3 | H15: 12.39 | I15: =G15*H15 | J15: =I15
B16: Database | C16: Amazon RDS for PostgreSQL | D16: Primary with a Multi-AZ standby: control DB + DB per tenant | E16: me-central-1 (UAE) | F16: PostgreSQL 16, db.m6g.xlarge (4 vCPU, 16 GiB, Graviton; the D4ds v5 line), Multi-AZ DB instance (synchronous standby in another AZ, automatic failover), $0.772/h, twice the single-AZ rate. Multi-AZ on every production tier (ADR-0060). RDS, not Aurora (see the notes) | G16: 1 | H16: 563.56 | I16: =G16*H16 | J16: =I16
B17: Database | C17: Amazon RDS for PostgreSQL | D17: Storage, primary and standby | E17: me-central-1 (UAE) | F17: gp3 256 GB Multi-AZ at $0.279 per GB-month; automated backups (PITR up to 35 days) free up to the provisioned storage, then $0.1045 per GB-month (not priced) | G17: 1 | H17: 71.42 | I17: =G17*H17 | J17: =I17
B18: Database | C18: Amazon RDS for PostgreSQL | D18: Read replicas (operational reads; gate checks never read here) | E18: me-central-1 (UAE) | F18: db.m6g.xlarge single-AZ ($0.386/h) + gp3 256 GB ($0.14 per GB-month) each, in different AZs | G18: 2 | H18: 317.62 | I18: =G18*H18 | J18: =I18
B19: Database | C19: Amazon RDS for PostgreSQL | D19: Reporting replica (lag-tolerant, no writes) | E19: me-central-1 (UAE) | F19: db.m6g.large (2 vCPU, 8 GiB; the D2ds v5 line), $0.193/h, + gp3 256 GB | G19: 1 | H19: 176.73 | I19: =G19*H19 | J19: =I19
B20: Database | C20: Amazon RDS for PostgreSQL | D20: AI log database (decision records, prompts) | E20: me-central-1 (UAE) | F20: db.m6g.xlarge single-AZ + gp3 1,024 GB. A writable instance of its own (ADR-0020, amended by ADR-0049) | G20: 1 | H20: 425.14 | I20: =G20*H20 | J20: =I20
B21: Cache | C21: Amazon ElastiCache (Valkey) | D21: Sessions, idempotency keys, per-tenant request budgets (ADR-0064), waiting-room positions (ADR-0066), the one-second browse cache (ADR-0065, proposed), AI features | E21: me-central-1 (UAE) | F21: cache.r7g.large (13.07 GiB; the B10 12 GB line), $0.2142/h, a primary and one replica in another AZ, Multi-AZ with automatic failover. Valkey is the Redis-compatible engine ElastiCache prices lowest (Redis OSS $0.2678/h) | G21: 2 | H21: 156.37 | I21: =G21*H21 | J21: =I21
B22: Storage | C22: Amazon S3 | D22: Media (including venue 3D models and navigation files, ADR-0069), exports, Qdrant snapshots, database dumps | E22: me-central-1 (UAE) | F22: S3 Standard, 2,048 GB at $0.025 per GB-month, stored across AZs (the ZRS line), me-central-1 only; requests not priced | G22: 1 | H22: 51.2 | I22: =G22*H22 | J22: =I22
B23: Storage | C23: Amazon ECR | D23: Images for the five deployables | E23: me-central-1 (UAE) | F23: About 100 GB at $0.10 per GB-month (an assumption) | G23: 1 | H23: 10 | I23: =G23*H23 | J23: =I23
... B25: Security | C25: AWS KMS | D25: Platform keys and per-tenant keys (ADR-0063 wraps each tenant's data key; BYOK) | E25: me-central-1 (UAE) | F25: Customer managed keys at $1 a month; KMS keeps keys in FIPS 140-3 validated HSMs, so no premium tier is needed (Key Vault Premium on Azure). 5 platform keys budgeted; +$1 a tenant a month (about $200 at 200 tenants); BYOK by importing key material; requests $0.03 per 10,000 (not priced) | G25: 5 | H25: 1 | I25: =G25*H25 | J25: =I25
B26: Network | C26: Amazon CloudFront | D26: Single entry for web, apps and APIs; the on-sale waiting-room page from its cache (ADR-0066) | E26: Global (edge) | F26: 2,048 GB to viewers in the Middle East at $0.110/GB ($225.28) + about 50 million HTTPS requests at $0.0120 per 10,000 ($60.00). Origin fetches from the ALB are free; a VPC origin keeps the ALB private (no charge line in the price list, to confirm) | G26: 1 | H26: 285.28 | I26: =G26*H26 | J26: =2*H26
B27: Network | C27: AWS WAF | D27: WAF on CloudFront: OWASP and bot rules, rate rules per client IP | E27: Global (edge) | F27: Web ACL $5 + about 8 rules and managed rule groups (AWS managed core rule set for OWASP, rate-based rules per client IP) at $1 ($8.00) + 50 million requests at $0.60 per million ($30.00) + Bot Control (common) $10 + 40 million requests beyond the first 10 million at $1 per million ($40.00). A CloudFront web ACL is global: the me-central-1 rates, to confirm on the bill | G27: 1 | H27: 93 | I27: =G27*H27 | J27: =2*H27
B28: Network | C28: Elastic Load Balancing (ALB) | D28: Ingress: an internal Application Load Balancer, CloudFront's VPC origin (the internal LB and Private Link line) | E28: me-central-1 (UAE) | F28: $0.028224/h ($20.60) + about 2 LCU on average at $0.00896 per LCU-hour ($13.08, an assumption). AWS Load Balancer Controller on the system node group | G28: 1 | H28: 33.68 | I28: =G28*H28 | J28: =2*H28
B29: Network | C29: NAT Gateway | D29: Static egress IPs for payment, e-invoicing and messaging allow-lists | E29: me-central-1 (UAE) | F29: 3 zonal NAT Gateways, one per AZ at $0.0528/h ($115.63) + 1 TB processed at $0.0528/GB ($54.07) + 3 Elastic IPs at $0.005/h ($10.95). Three IPs to allow-list, not one; a Regional NAT Gateway (same hourly rate) may present fewer, to confirm | G29: 1 | H29: 180.65 | I29: =G29*H29 | J29: =I29
B30: Network | C30: Systems Manager Session Manager | D30: Administrative access only (the Azure Bastion line) | E30: me-central-1 (UAE) | F30: No charge line in the me-central-1 Systems Manager price list (11 September), to confirm; no inbound port, no SSH keys; sessions logged to CloudWatch | G30: 1 | H30: 0 | I30: =G30*H30 | J30: =I30
B31: Network | C31: AWS PrivateLink (VPC endpoints) | D31: Private endpoints and private DNS (the Private Link line) | E31: me-central-1 (UAE) | F31: 6 interface endpoints (ECR api and dkr, Secrets Manager, KMS, STS, CloudWatch Logs) x 3 AZs at $0.0121/h ($158.99) + about 100 GB processed at $0.01/GB ($1.00); S3 through a gateway endpoint (free); Route 53 private hosted zones | G31: 1 | H31: 159.99 | I31: =G31*H31 | J31: =I31
B32: Network | C32: Data transfer out | D32: Egress through the NAT Gateways to providers | E32: me-central-1 (UAE) | F32: About 200 GB a month: the first 100 GB free, then $0.117/GB ($11.70). The ALB-to-CloudFront traffic is free; the web traffic is in the CloudFront line | G32: 1 | H32: 11.7 | I32: =G32*H32 | J32: =2*H32
B33: Operations | C33: Amazon CloudWatch | D33: Logs, metrics, alerts, dashboards | E33: me-central-1 (UAE) | F33: About 60 GB of logs ingested at $0.63/GB ($37.80), stored at $0.033 per GB-month ($1.98 in the first month, growing with retention), about 200 custom metrics at $0.30 ($60.00) | G33: 1 | H33: 99.78 | I33: =G33*H33 | J33: =I33
B34: Operations | C34: AWS Backup | D34: Snapshots of the Qdrant and broker volumes | E34: me-central-1 (UAE) | F34: Daily EBS snapshots, 30 days, in me-central-1: about 500 GB of incremental snapshot storage at $0.055 per GB-month (an assumption) | G34: 1 | H34: 27.5 | I34: =G34*H34 | J34: =I34
B35: Operations | C35: GuardDuty, Inspector, Security Hub | D35: Threat detection for EKS, RDS and the account, node scanning, posture (the Defender for Cloud line) | E35: me-central-1 (UAE) | F35: GuardDuty EKS Runtime Monitoring 70 vCPU x $1.58 ($110.60); RDS Protection 18 vCPU x $1.03 ($18.54); VPC flow and DNS logs about 20 GB x $1.25 ($25.00) and about 2 million CloudTrail events ($10.00); Inspector 14 instances x 730 h x $0.0021 ($21.46); Security Hub Essentials 14 instances x 730 h x $0.0056944 ($58.20). Volumes are assumptions | G35: 1 | H35: 243.8 | I35: =G35*H35 | J35: =I35
B36: AI (usage) | C36: LLM providers | D36: Language model calls (re-billed per token, AI-D02) | E36: me-central-1 (UAE) | F36: Usage-based; not a fixed hosting cost | G36: 1 | H36: 0 | I36: =G36*H36 | J36: =I36
F37: USD - Total cost per month | I37: =SUM(I7:I36) | J37: =SUM(J7:J36)
F38: AED - Total cost per month | I38: =I37*$C$3 | J38: =J37*$C$3
F39: AED - Total cost per year | I39: =I38*12
F40: AED - Total price per year with margin | I40: =I39*(1+$C$4)
B42: Notes - Production
B43: Prices: AWS Price List API, public bulk offer files (pricing.us-east-1.amazonaws.com/offers/v1.0/aws/<service>/current/me-central-1/index.json; CloudFront's global file), region me-central-1 (Middle East, UAE), on demand, Linux, 730 hours a month, pulled 4 October 2026 (files published 11 September to 3 October 2026; each rate names its file and date in AWS_RATE). Savings Plans or reserved instances (1 or 3 years) lower compute by roughly 30-60%; confirm each line in the AWS Pricing Calculator for me-central-1 before quoting.
B44: The same cell as the Azure sheets, service for service (the AWS LLD, TICVAI-LLD-AWS.md, has the mapping): the same five node groups and ADR-0061 floors, the same stores, the same entry. Region me-central-1 (Middle East, UAE), three AZs; every store stays in the UAE.
...

Sheet Deployables
A1: Deployable | B1: What it is | C1: Modules | D1: Runs on | E1: Replica floor (ADR-0061)
A2: commerce | B2: The sale path: order, payment and ledger commit in one transaction. Autoscales on requests per second. | C2: Catalogue, Identity, Ledger, Order, Tenancy, Wallet | D2: Workload node group | E2: 3: One per zone: the sale path survives a zone loss without a cold start
A3: access | B3: The gate hot path, flat high rate, offline package. The same module code builds the venue edge node. | C3: Access | D3: Workload node group (and the venue edge node) | E3: 2: Cloud side only; the gate decides locally (ADR-0013)
A4: operations | B4: Back office and engagement. Nothing that takes money waits on it. | C4: CrossRegion, Fnb, Inventory, Marketing, Platform, Reporting, Retail, VenueOps, WhiteLabel | D4: Workload node group | E4: 2: Back office tolerates a short scale-out
A5: ticvai-ai | B5: AI, in Python, isolated (ADR-0020): three process groups, read-only on the transactional schemas. | C5: Ai | D5: AI GPU node group (tainted) | E5: 3: ai-realtime 2; ai-interactive 1; ai-batch 0 (real-time 3 in a large cell)
A6: workers | B6: No module of its own: the outbox relay (one per region, ADR-0058), every module's event consumers and scheduled jobs. Scales on queue depth. | C6: - | D6: Workload node group | E6: 2: Relay leases fail over between replicas (ADR-0058, amended 1 October)
A7: Total at the floor | E7: 12 a cell; 13 in a large cell
A9: Data stores
A10: PostgreSQL 16 | B10: Control DB and one database per tenant, Multi-AZ on every production tier (ADR-0060); read replicas; reporting replica; AI log DB | D10: Amazon RDS for PostgreSQL (not Aurora)
A11: Qdrant | B11: Vectors; one collection per tenant, collection-scoped JWT (ADR-0049) | D11: qdrant node group
A12: Redis | B12: Sessions, idempotency, per-tenant request budgets (ADR-0064), waiting-room positions (ADR-0066), the one-second browse cache (ADR-0065, proposed) | D12: Amazon ElastiCache for Valkey
A13: Event broker | B13: RabbitMQ recommended or Kafka, the client's choice by 12 October (ADR-0057); outbox relay per region in workers (ADR-0058, amended 1 October) | D13: broker node group while self-run; Amazon MQ for RabbitMQ if managed
A14: Object storage | B14: Media (including venue 3D models and navigation files, ADR-0069), exports, snapshots, dumps | D14: Amazon S3

Sheet Network
A1: Subnet | B1: Block | C1: Per-AZ subnets (a, b, c) | D1: Holds | E1: Rule
A2: ingress | B2: 10.20.0.0/24 | C2: 10.20.0.0/26, 10.20.0.64/26, 10.20.0.128/26 | D2: Internal Application Load Balancer, CloudFront's VPC origin (snet-ingress) | E2: Security group: inbound 443 only from the CloudFront origin-facing prefix list
A3: public | B3: 10.20.2.0/24 | C3: 10.20.2.0/26, 10.20.2.64/26, 10.20.2.128/26 | D3: NAT Gateways and their Elastic IPs, nothing else (takes snet-agc's reserved block) | E3: Route to the Internet gateway; no instance, no load balancer
A4: eks-system | B4: 10.20.4.0/22 | C4: 10.20.4.0/24, 10.20.5.0/24, 10.20.6.0/24 | D4: EKS system node group and the ingress controller pods | E4: Egress through the NAT Gateway of its AZ
A5: eks-workload | B5: 10.20.8.0/21 | C5: 10.20.8.0/23, 10.20.10.0/23, 10.20.12.0/23 | D5: Workload node group: commerce, access, operations, workers | E5: Network policy: inbound from the ingress controller; egress through the NAT Gateway
A6: eks-ai | B6: 10.20.16.0/22 | C6: 10.20.16.0/24, 10.20.17.0/24, 10.20.18.0/24 | D6: AI GPU node group (the only AI group): ticvai-ai, BGE-M3 and its reranker, Presidio and the Arabic NER | E6: Network policy: inbound from the ingress controller and the workload group; read-only role on transactional schemas (ADR-0020, amended by ADR-0049)
A7: eks-data | B7: 10.20.20.0/23 | C7: 10.20.20.0/25, 10.20.20.128/25, 10.20.21.0/25 | D7: qdrant node group and, while the broker is self-run, the broker node group; both tainted ticvai.io/pool=data | E7: Network policy: inbound from the workload and AI groups only; Qdrant needs each tenant's collection-scoped JWT
A8: db | B8: 10.20.24.0/24 | C8: 10.20.24.0/26, 10.20.24.64/26, 10.20.24.128/26 | D8: RDS DB subnet group: the primary and its Multi-AZ standby, replicas, the AI log DB | E8: Security group: 5432 from the EKS node and pod security groups; not publicly accessible
A9: endpoints | B9: 10.20.25.0/24 | C9: 10.20.25.0/26, 10.20.25.64/26, 10.20.25.128/26 | D9: Interface VPC endpoints, the ElastiCache subnet group (and Amazon MQ if chosen) | E9: Security group: inbound from the EKS subnets only; private DNS on; no public endpoint
A10: (none: no Bastion) | B10: 10.20.26.0/26 | C10: - | D10: Not created: Session Manager reaches the nodes through the ssm endpoints or the NAT Gateway | E10: Reserved
A11: tgw-attach | B11: 10.20.27.0/27 | C11: 10.20.27.0/28, 10.20.27.16/28 (a third /28 needs 10.20.27.32/28) | D11: Transit Gateway or VPN attachment for dedicated-tier venues' site-to-site VPN (GatewaySubnet) | E11: Created when a venue needs it
A12: pods (secondary CIDR) | B12: 100.64.0.0/16 | C12: 100.64.0.0/18, 100.64.64.0/18, 100.64.128.0/18 | D12: Pod addresses: VPC CNI custom networking, so pods do not use the node subnets (the CNI Overlay range on Azure) | E12: Must not overlap the client's ranges or a venue LAN on the VPN
A13: EKS services | B13: 10.100.0.0/16 | C13: - | D13: Kubernetes service range (service_ipv4_cidr) | E13: Internal only

Sheet Service map
A1: Azure (UAE North) | B1: AWS (me-central-1, UAE)
A2: Azure Front Door Premium + WAF (waiting-room page from cache; built-in DDoS protection) | B2: Amazon CloudFront + AWS WAF (managed core rule set, Bot Control, rate-based rules); the waiting-room page from CloudFront's cache; AWS Shield Standard for DDoS
A3: Internal load balancer + Private Link service; AKS App Routing (Gateway API) | B3: Internal Application Load Balancer (AWS Load Balancer Controller, Gateway API or Ingress), CloudFront VPC origin
A4: AKS, Standard tier: system, workload, AI GPU, qdrant and broker pools | B4: Amazon EKS: system, workload, AI GPU, qdrant and broker managed node groups, the same taints
A5: AKS AI GPU pool: NV6ads A10 v5 (1/6 A10, 4 GB) | B5: EKS GPU node group: g6.2xlarge (1 x L4, 24 GB)
A6: Azure Database for PostgreSQL Flexible Server 16, zone-redundant HA | B6: Amazon RDS for PostgreSQL 16, Multi-AZ DB instance (not Aurora)
A7: Read replicas x2, reporting replica, AI log DB | B7: RDS read replicas x2 (db.m6g.xlarge), a reporting replica (db.m6g.large), an AI log DB instance
A8: Azure Managed Redis (Balanced B10, HA) | B8: Amazon ElastiCache for Valkey (cache.r7g.large, primary + replica, Multi-AZ)
A9: Event broker self-run on the AKS broker pool (CloudAMQP recommended) | B9: Self-run on the EKS broker node group (RabbitMQ Cluster Operator), as on Azure; Amazon MQ for RabbitMQ the managed option
A10: Qdrant on the AKS qdrant pool, Premium SSD | B10: Qdrant on the EKS qdrant node group (r6i.xlarge), EBS gp3
A11: Managed Disks (Premium SSD) | B11: Amazon EBS gp3
A12: Blob storage (ZRS) | B12: Amazon S3 Standard (multi-AZ), S3 gateway endpoint
... A24: DR in UAE Central (ADR-0060) | B24: OPEN: AWS has one UAE region (see Disaster recovery)

Sheet DR (open)
A1: Option | B1: What it is | C1: UAE residency | D1: Consequences
A2: A. Multi-AZ only, backups in-region | B2: Everything in me-central-1 across three AZs; RDS automated backups and snapshots, AWS Backup vaults (a logically air-gapped vault included) and S3 copies all in me-central-1 | C2: Keeps every store in the UAE (ADR-0009, the condition Qdrant was approved on) | D2: No region-level DR: a regional outage stops the cloud services until AWS restores the region (venues keep running on their edge nodes). RPO is the last in-region backup, RTO the region's recovery, with no bound we control. The cheapest; the tenant-selectable DR module of ADR-0060 has nowhere to go
A3: B. Cross-region to Bahrain (me-south-1) | B3: An RDS cross-region read replica or snapshot copies, S3 replication, and a standby EKS cell in me-south-1 | C3: Breaks UAE residency: Bahrain is outside the UAE. Needs the client's (and, for regulated data, the regulator's) written acceptance, and reverses the basis Qdrant was approved on | D3: Real regional DR (RPO minutes with a replica, RTO hours with a rehearsed runbook), as Azure's UAE Central gives. Adds a second cell's cost and cross-region transfer (about $0.09 per GB out of me-central-1 to me-south-1)
A4: C. On-premises or another provider in the UAE | B4: A recovery site in the UAE outside AWS: the client's data centre, a UAE colocation, or Azure UAE North or Central as the DR side of an AWS primary | C4: Keeps every store in the UAE | D4: Cross-provider replication (PostgreSQL logical replication or dumps, S3 to Blob or object-store copies, Qdrant snapshots), two sets of tooling and skills, Internet egress at $0.117 per GB; the most work to build and rehearse
A5: Status | B5: OPEN, not decided (CHG-R3-001). AWS has one region in the UAE (me-central-1, three AZs); Azure's DR region, UAE Central, has no AWS counterpart. The options and what each costs are below; the choice is Chinmay's and the client's, because two of the three trade residency or money against recovery.

Sheet AWS rates
A1: Key | B1: USD | C1: Per | D1: What | E1: Offer file and its publication date
A2: eks | B2: 0.1 | C2: hour | D2: EKS cluster, standard support | E2: AmazonEKS 2026-09-28
A3: m6i.large | B3: 0.1177 | C3: hour | D3: EC2 m6i.large (2 vCPU, 8 GiB), Linux | E3: AmazonEC2 2026-09-25
A4: m6i.xlarge | B4: 0.2354 | C4: hour | D4: EC2 m6i.xlarge (4 vCPU, 16 GiB), Linux | E4: AmazonEC2 2026-09-25
A5: m6i.2xlarge | B5: 0.4708 | C5: hour | D5: EC2 m6i.2xlarge (8 vCPU, 32 GiB), Linux | E5: AmazonEC2 2026-09-25
A6: m6i.4xlarge | B6: 0.9416 | C6: hour | D6: EC2 m6i.4xlarge (16 vCPU, 64 GiB), Linux | E6: AmazonEC2 2026-09-25
A7: r6i.large | B7: 0.1551 | C7: hour | D7: EC2 r6i.large (2 vCPU, 16 GiB), Linux | E7: AmazonEC2 2026-09-25
A8: r6i.xlarge | B8: 0.3102 | C8: hour | D8: EC2 r6i.xlarge (4 vCPU, 32 GiB), Linux | E8: AmazonEC2 2026-09-25
A9: g6.xlarge | B9: 0.98824 | C9: hour | D9: EC2 g6.xlarge (4 vCPU, 16 GiB, 1 x L4 24 GB), Linux | E9: AmazonEC2 2026-09-25
A10: g6.2xlarge | B10: 1.20043 | C10: hour | D10: EC2 g6.2xlarge (8 vCPU, 32 GiB, 1 x L4 24 GB), Linux | E10: AmazonEC2 2026-09-25
A11: g5.xlarge | B11: 1.234 | C11: hour | D11: EC2 g5.xlarge (4 vCPU, 16 GiB, 1 x A10G 24 GB), Linux | E11: AmazonEC2 2026-09-25
A12: g5.2xlarge | B12: 1.48669 | C12: hour | D12: EC2 g5.2xlarge (8 vCPU, 32 GiB, 1 x A10G 24 GB), Linux | E12: AmazonEC2 2026-09-25
A13: gp3 | B13: 0.0968 | C13: GB-month | D13: EBS gp3 volume | E13: AmazonEC2 2026-09-25
... A58: sh-ec2 | B58: 0.0056944 | C58: instance-hour | D58: Security Hub Essentials, per EC2 instance | E58: AWSSecurityHub 2026-09-30
A60: To confirm | D60: g6 capacity in each of me-central-1's three AZs (the Price List API lists g6.2xlarge for the region, not per AZ); whether a Regional NAT Gateway presents one egress IP for all three AZs (priced here as three zonal gateways, three IPs to allow-list); CloudFront VPC origins and Systems Manager Session Manager: no charge line in the price list files; AWS WAF on CloudFront is a global web ACL: the me-central-1 WAF rates are used, to check against the bill; S3 and ECR requests, KMS and Secrets Manager API calls, RDS backup beyond the free allocation: usage, not priced; CloudAMQP on AWS me-central-1 (the broker the client may take; on Azure it is in UAE North); Aurora I/O volume (Aurora is not chosen; its I/O cost is unknown until the load test); Volumes behind usage lines (logs, metrics, LCUs, GuardDuty data, requests): assumptions, as on the Azure sheets | E60: AWS Price List API, public bulk offer files (pricing.us-east-1.amazonaws.com/offers/v1.0/aws/<service>/current/me-central-1/index.json; CloudFront's global file), region me-central-1 (Middle East, UAE), on demand, Linux, 730 hours a month, pulled 4 October 2026 (files published 11 September to 3 October 2026; each rate names its file and date in AWS_RATE).

Sheet Azure vs AWS
A1: TICVAI - Azure UAE North against AWS me-central-1 (USD a month, production unless said)
B3: AED per USD | C3: 3.6725 | D3: Edit the rate, the margin and any unit price; every total is a formula.
B4: Margin | C4: 0.2 | D4: Azure: Azure Retail Prices API (prices.azure.com), region uaenorth, pay as you go, 730 hours a month, pulled 30 September 2026; vendor prices (CloudAMQP, Confluent) from the vendors' pages the same day. Working: docs/active/infra-answers-30-september.md, section 4b. AWS: AWS Price List API, public bulk offer files (pricing.us-east-1.amazonaws.com/offers/v1.0/aws/<service>/current/me-central-1/index.json; CloudFront's global file), region me-central-1 (Middle East, UAE), on demand, Linux, 730 hours a month, pulled 4 October 2026 (files published 11 September to 3 October 2026; each rate names its file and date in AWS_RATE).
A6: Line | B6: Azure UAE North (USD / month) | C6: AWS me-central-1 (USD / month) | D6: AWS - Azure (USD) | E6: AWS against Azure | F6: Azure (AED / month) | G6: AWS (AED / month) | H6: AWS (AED a year with margin)
A7: Stage 1 production (launch) | B7: 2254.47 | C7: ='Stages'!I27 | D7: =C7-B7 | E7: =C7/B7-1 | F7: =B7*$C$3 | G7: =C7*$C$3 | H7: =G7*12*(1+$C$4)
A8: Stage 1 pre-production | B8: 566 | C8: ='Stages'!I47 | D8: =C8-B8 | E8: =C8/B8-1 | F8: =B8*$C$3 | G8: =C8*$C$3 | H8: =G8*12*(1+$C$4)
A9: Stage 1 in all | B9: 2820.47 | C9: =C7+C8 | D9: =C9-B9 | E9: =C9/B9-1 | F9: =B9*$C$3 | G9: =C9*$C$3 | H9: =G9*12*(1+$C$4)
A10: Full cell (Stage 2) without zone-level HA | B10: 5327.27 | C10: ='Infra without HA'!I37 | D10: =C10-B10 | E10: =C10/B10-1 | F10: =B10*$C$3 | G10: =C10*$C$3 | H10: =G10*12*(1+$C$4)
A11: Full cell (Stage 2) with high availability | B11: 8295.04 | C11: ='Infra with High Availability'!I37 | D11: =C11-B11 | E11: =C11/B11-1 | F11: =B11*$C$3 | G11: =C11*$C$3 | H11: =G11*12*(1+$C$4)
A12: Pre-production beside the full cell | B12: 1535.5 | C12: ='Infra with High Availability'!I69 | D12: =C12-B12 | E12: =C12/B12-1 | F12: =B12*$C$3 | G12: =C12*$C$3 | H12: =G12*12*(1+$C$4)
A13: Stage 0 (reference only) | B13: 1161.43 | C13: ='Stages'!I58 | D13: =C13-B13 | E13: =C13/B13-1 | F13: =B13*$C$3 | G13: =C13*$C$3 | H13: =G13*12*(1+$C$4)
A15: Notes
A16: The same cell on both clouds, service for service (TICVAI-LLD-AWS.md has the mapping). The AWS column is a formula on this workbook's sheets, so it follows any unit price edited there; the Azure column is the Azure workbook's totals as generated on 4 October 2026.
A17: Where AWS costs more: the EKS control plane at every stage (no free tier), the GPU node (a whole L4 with 24 GB against Azure's 4 GB A10 slice), three NAT Gateways for HA, EBS root volumes on every node, PrivateLink endpoints per AZ. Where it costs less: the edge (CloudFront + WAF against Front Door Premium), the security tooling (GuardDuty, Inspector, Security Hub against Defender for Cloud), Bastion (Session Manager has no charge line), the cache and the read replicas.
A18: Disaster recovery is not in either column: Azure's DR module (UAE Central) is bought per tenant, and on AWS DR is open (one AWS region in the UAE; see TICVAI-LLD-AWS.md).
A19: On-demand list prices on both sides; reserved capacity or savings plans move both by a similar 30-60% on compute.
